Workbook

Sheet Historical responsibility T
M2: Global Carbon Budget 2021 Friedlingstein, et al., 2021 | N2: IAMC AR6 Scenario Explorer Model: REMIND-MAgPIE 2.1-4.3 Scenario: DeepElec_SSP2_ HighRE_Budg900 | O2: Statistics Sweden Population Projections | P2: SSP Database - Version 2.0 Data for SSP2
B3: Territorial emissions Sweden fossil (excl. LUC) | D3: Population | E3: Emissions | F3: Allocation per capita givet DeepElec_SSP2_ HighRE_Budg900 | K3: Historic fossil emissions | L3: Historic LUC emissions | M3: Scenario (World incl. LUC) | N3: Scenario minus bunkers | O3: Internation bunkers | P3: Bunkers (%) of total | R3: Population SSP2 | S3: Scenario per capita
B4: MtC | C4: MtCO2 | E4: tCO2/capita | F4: MtCO2 | K4: GtC | L4: GtC | M4: GtC | N4: GtC | O4: MtC | R4: millions | S4: tCO2/capita
A5: 1959 | B5: 11.568886 | C5: =B5*44/12 -> 42.419247 | D5: 7462823 | E5: =C5*1000000/D5 -> 5.6840752 | F5: =D5*S5/1000000 -> 38.612323 | J5: 1959 | K5: 2.4171328 | L5: 1.8455188 | M5: =L5+K5 -> 4.2626516 | N5: =M5-O5/1000 -> 4.2044176 | O5: 58.234 | P5: =O5/1000/M5 -> 0.013661449 | R5: 2979.5762 | S5: =N5*1000000000*44/12*1/(R5*1000000) -> 5.1739566
A6: 1960 | B6: 13.419902 | C6: =B6*44/12 -> 49.206307 | D6: 7497967 | E6: =C6*1000000/D6 -> 6.5626198 | F6: =D6*S6/1000000 -> 39.413259 | J6: 1960 | K6: 2.5621753 | L6: 1.8537116 | M6: =L6+K6 -> 4.4158869 | N6: =M6-O6/1000 -> 4.3508979 | O6: 64.988958 | P6: =O6/1000/M6 -> 0.014717079 | R6: 3034.9497 | S6: =N6*1000000000*44/12*1/(R6*1000000) -> 5.2565261
A7: 1961 | B7: 13.318643 | C7: =B7*44/12 -> 48.835023 | D7: 7542028 | E7: =C7*1000000/D7 -> 6.4750519 | F7: =D7*S7/1000000 -> 39.00446 | J7: 1961 | K7: 2.5705877 | L7: 1.8621203 | M7: =L7+K7 -> 4.432708 | N7: =M7-O7/1000 -> 4.3608606 | O7: 71.847433 | P7: =O7/1000/M7 -> 0.016208474 | R7: 3091.8435 | S7: =N7*1000000000*44/12*1/(R7*1000000) -> 5.1716143
A8: 1962 | B8: 13.99361 | C8: =B8*44/12 -> 51.309903 | D8: 7581148 | E8: =C8*1000000/D8 -> 6.7680915 | F8: =D8*S8/1000000 -> 38.624394 | J8: 1962 | K8: 2.6613709 | L8: 1.7905989 | M8: =L8+K8 -> 4.4519698 | N8: =M8-O8/1000 -> 4.3774766 | O8: 74.493219 | P8: =O8/1000/M8 -> 0.016732642 | R8: 3150.4208 | S8: =N8*1000000000*44/12*1/(R8*1000000) -> 5.0947948
A9: 1963 | B9: 15.096358 | C9: =B9*44/12 -> 55.353314 | D9: 7627507 | E9: =C9*1000000/D9 -> 7.2570649 | F9: =D9*S9/1000000 -> 38.126238 | J9: 1963 | K9: 2.8034634 | L9: 1.651862 | M9: =L9+K9 -> 4.4553254 | N9: =M9-O9/1000 -> 4.3773407 | O9: 77.984751 | P9: =O9/1000/M9 -> 0.017503716 | R9: 3211.001 | S9: =N9*1000000000*44/12*1/(R9*1000000) -> 4.9985189
A10: 1964 | B10: 16.476002 | C10: =B10*44/12 -> 60.412006 | D10: 7695200 | E10: =C10*1000000/D10 -> 7.850609 | F10: =D10*S10/1000000 -> 38.21669 | J10: 1964 | K10: 2.9557499 | L10: 1.5641112 | M10: =L10+K10 -> 4.5198611 | N10: =M10-O10/1000 -> 4.4344272 | O10: 85.433825 | P10: =O10/1000/M10 -> 0.01890187 | R10: 3273.9783 | S10: =N10*1000000000*44/12*1/(R10*1000000) -> 4.9663024
A11: 1965 | B11: 17.07484 | C11: =B11*44/12 -> 62.607746 | D11: 7772506 | E11: =C11*1000000/D11 -> 8.055027 | F11: =D11*S11/1000000 -> 37.700968 | J11: 1965 | K11: 3.0889418 | L11: 1.4171726 | M11: =L11+K11 -> 4.5061144 | N11: =M11-O11/1000 -> 4.4178638 | O11: 88.250571 | P11: =O11/1000/M11 -> 0.019584627 | R11: 3339.5836 | S11: =N11*1000000000*44/12*1/(R11*1000000) -> 4.850555
A12: 1966 | B12: 19.791856 | C12: =B12*44/12 -> 72.570138 | D12: 7843088 | E12: =C12*1000000/D12 -> 9.2527507 | F12: =D12*S12/1000000 -> 37.908184 | J12: 1966 | K12: 3.2388801 | L12: 1.3488657 | M12: =L12+K12 -> 4.5877458 | N12: =M12-O12/1000 -> 4.4922528 | O12: 95.492929 | P12: =O12/1000/M12 -> 0.020814782 | R12: 3407.9226 | S12: =N12*1000000000*44/12*1/(R12*1000000) -> 4.8333238
A13: 1967 | B13: 18.812702 | C13: =B13*44/12 -> 68.979906 | D13: 7892774 | E13: =C13*1000000/D13 -> 8.7396276 | F13: =D13*S13/1000000 -> 38.366478 | J13: 1967 | K13: 3.3418105 | L13: 1.3722228 | M13: =L13+K13 -> 4.7140333 | N13: =M13-O13/1000 -> 4.6118646 | O13: 102.16879 | P13: =O13/1000/M13 -> 0.021673327 | R13: 3478.77 | S13: =N13*1000000000*44/12*1/(R13*1000000) -> 4.8609624
A14: 1968 | B14: 21.180685 | C14: =B14*44/12 -> 77.662513 | D14: 7931193 | E14: =C14*1000000/D14 -> 9.7920342 | F14: =D14*S14/1000000 -> 39.264642 | J14: 1968 | K14: 3.5238302 | L14: 1.3795323 | M14: =L14+K14 -> 4.9033626 | N14: =M14-O14/1000 -> 4.7952983 | O14: 108.06425 | P14: =O14/1000/M14 -> 0.022038805 | R14: 3551.5991 | S14: =N14*1000000000*44/12*1/(R14*1000000) -> 4.9506602
A15: 1969 | B15: 23.575637 | C15: =B15*44/12 -> 86.444001 | D15: 8004270 | E15: =C15*1000000/D15 -> 10.799736 | F15: =D15*S15/1000000 -> 39.96305 | J15: 1969 | K15: 3.7576083 | L15: 1.2924244 | M15: =L15+K15 -> 5.0500326 | N15: =M15-O15/1000 -> 4.9369078 | O15: 113.12485 | P15: =O15/1000/M15 -> 0.022400816 | R15: 3625.6806 | S15: =N15*1000000000*44/12*1/(R15*1000000) -> 4.9927164
A16: 1970 | B16: 25.187507 | C16: =B16*44/12 -> 92.354192 | D16: 8081229 | E16: =C16*1000000/D16 -> 11.428236 | F16: =D16*S16/1000000 -> 41.95663 | J16: 1970 | K16: 4.0662051 | L16: 1.2865143 | M16: =L16+K16 -> 5.3527194 | N16: =M16-O16/1000 -> 5.2336608 | O16: 119.05865 | P16: =O16/1000/M16 -> 0.022242648 | R16: 3696.186 | S16: =N16*1000000000*44/12*1/(R16*1000000) -> 5.1918625
... A64: 2018 | B64: 11.488921 | C64: =B64*44/12 -> 42.126045 | D64: 10230185 | E64: =C64*1000000/D64 -> 4.1178185 | F64: =D64*S64/1000000 -> 53.046493 | J64: 2018 | K64: 10.000813 | L64: 1.0528217 | M64: =L64+K64 -> 11.053635 | N64: =M64-O64/1000 -> 10.708986 | O64: 344.64899 | P64: =O64/1000/M64 -> 0.031179697 | R64: 7572.6276 | S64: =N64*1000000000*44/12*1/(R64*1000000) -> 5.1852916
A65: 2019 | B65: 11.172726 | C65: =B65*44/12 -> 40.966661 | D65: 10327553 | E65: =C65*1000000/D65 -> 3.9667345 | F65: =D65*S65/1000000 -> 53.096761 | G65: =C65/C36-1 -> -0.28654492 | H65: =E65/E36-1 -> -0.40653622 | I65: =S65/S36-1 -> 0.029274307 | J65: 2019 | K65: 10.016143 | L65: 1.0440531 | M65: =L65+K65 -> 11.060196 | N65: =M65-O65/1000 -> 10.71755 | O65: 342.64617 | P65: =O65/1000/M65 -> 0.030980117 | R65: 7643.5719 | S65: =N65*1000000000*44/12*1/(R65*1000000) -> 5.1412721
A66: 2020 | B66: 10.541884 | C66: =B66*44/12 -> 38.653576 | D66: 10379295 | E66: =C66*1000000/D66 -> 3.7241041 | F66: =D66*S66/1000000 -> 49.837722 | J66: 2020 | K66: 9.4999578 | L66: 0.87608978 | M66: =L66+K66 -> 10.376048 | N66: =M66-O66/1000 -> 10.10247 | O66: 273.57723 | P66: =O66/1000/M66 -> 0.026366227 | R66: 7714.5161 | S66: =N66*1000000000*44/12*1/(R66*1000000) -> 4.8016481
A67: 2021 | B67: =B66*1.021 -> 10.763264 | C67: =C66*1.021 -> 39.465301 | D67: 10428301 | E67: =C67*1000000/D67 -> 3.784442 | F67: =D67*S67/1000000 -> 52.852463 | J67: 2021 | M67: 11.092523 | N67: =M67-O67/1000 -> 10.754242 | O67: =AVERAGE($O$61:$O$65)/AVERAGE($M$61:$M$65)*M67 -> 338.28048 | P67: =O67/1000/M67 -> 0.030496262 | R67: 7780.3578 | S67: =N67*1000000000*44/12*1/(R67*1000000) -> 5.0681758
A68: 2022 | D68: 10477130 | F68: =D68*S68/1000000 -> 49.791479 | J68: 2022 | M68: 10.489411 | N68: =M68-O68/1000 -> 10.169524 | O68: =AVERAGE($O$61:$O$65)/AVERAGE($M$61:$M$65)*M68 -> 319.88784 | P68: =O68/1000/M68 -> 0.030496262 | R68: 7846.1995 | S68: =N68*1000000000*44/12*1/(R68*1000000) -> 4.7523968
A69: 2023 | D69: 10523969 | F69: =D69*S69/1000000 -> 46.746137 | J69: 2023 | M69: 9.8863002 | N69: =M69-O69/1000 -> 9.584805 | O69: =AVERAGE($O$61:$O$65)/AVERAGE($M$61:$M$65)*M69 -> 301.4952 | P69: =O69/1000/M69 -> 0.030496262 | R69: 7912.0412 | S69: =N69*1000000000*44/12*1/(R69*1000000) -> 4.4418734
A70: 2024 | D70: 10569942 | F70: =D70*S70/1000000 -> 43.722306 | J70: 2024 | M70: 9.283189 | N70: =M70-O70/1000 -> 9.0000864 | O70: =AVERAGE($O$61:$O$65)/AVERAGE($M$61:$M$65)*M70 -> 283.10256 | P70: =O70/1000/M70 -> 0.030496262 | R70: 7977.8829 | S70: =N70*1000000000*44/12*1/(R70*1000000) -> 4.1364755
A71: 2025 | D71: 10616595 | F71: =D71*S71/1000000 -> 40.726078 | J71: 2025 | M71: 8.6800778 | N71: =M71-O71/1000 -> 8.4153678 | O71: =AVERAGE($O$61:$O$65)/AVERAGE($M$61:$M$65)*M71 -> 264.70993 | P71: =O71/1000/M71 -> 0.030496262 | R71: 8043.7246 | S71: =N71*1000000000*44/12*1/(R71*1000000) -> 3.8360772
A72: 2026 | D72: 10663635 | F72: =D72*S72/1000000 -> 37.631703 | J72: 2026 | M72: 8.0442745 | N72: =M72-O72/1000 -> 7.7989542 | O72: =AVERAGE($O$61:$O$65)/AVERAGE($M$61:$M$65)*M72 -> 245.32031 | P72: =O72/1000/M72 -> 0.030496262 | R72: 8103.2494 | S72: =N72*1000000000*44/12*1/(R72*1000000) -> 3.5289751
A73: 2027 | D73: 10710874 | F73: =D73*S73/1000000 -> 34.557049 | J73: 2027 | M73: 7.4084713 | N73: =M73-O73/1000 -> 7.1825406 | O73: =AVERAGE($O$61:$O$65)/AVERAGE($M$61:$M$65)*M73 -> 225.93068 | P73: =O73/1000/M73 -> 0.030496262 | R73: 8162.7741 | S73: =N73*1000000000*44/12*1/(R73*1000000) -> 3.226352
A74: 2028 | D74: 10758403 | F74: =D74*S74/1000000 -> 31.501792 | J74: 2028 | M74: 6.7726681 | N74: =M74-O74/1000 -> 6.566127 | O74: =AVERAGE($O$61:$O$65)/AVERAGE($M$61:$M$65)*M74 -> 206.54106 | P74: =O74/1000/M74 -> 0.030496262 | R74: 8222.2989 | S74: =N74*1000000000*44/12*1/(R74*1000000) -> 2.9281104
A75: 2029 | D75: 10805992 | F75: =D75*S75/1000000 -> 28.464669 | J75: 2029 | M75: 6.1368649 | N75: =M75-O75/1000 -> 5.9497134 | O75: =AVERAGE($O$61:$O$65)/AVERAGE($M$61:$M$65)*M75 -> 187.15144 | P75: =O75/1000/M75 -> 0.030496262 | R75: 8281.8236 | S75: =N75*1000000000*44/12*1/(R75*1000000) -> 2.6341561
A76: 2030 | D76: 10853866 | F76: =D76*S76/1000000 -> 25.445772 | J76: 2030 | M76: 5.5010617 | N76: =M76-O76/1000 -> 5.3332998 | O76: =AVERAGE($O$61:$O$65)/AVERAGE($M$61:$M$65)*M76 -> 167.76182 | P76: =O76/1000/M76 -> 0.030496262 | R76: 8341.3484 | S76: =N76*1000000000*44/12*1/(R76*1000000) -> 2.3443971
A77: 2031 | D77: 10900734 | F77: =D77*S77/1000000 -> 23.718996 | J77: 2031 | M77: 5.1383005 | N77: =M77-O77/1000 -> 4.9816015 | O77: =AVERAGE($O$61:$O$65)/AVERAGE($M$61:$M$65)*M77 -> 156.69896 | P77: =O77/1000/M77 -> 0.030496262 | R77: 8394.597 | S77: =N77*1000000000*44/12*1/(R77*1000000) -> 2.1759082
A78: 2032 | D78: 10946282 | F78: =D78*S78/1000000 -> 21.997028 | J78: 2032 | M78: 4.7755393 | N78: =M78-O78/1000 -> 4.6299032 | O78: =AVERAGE($O$61:$O$65)/AVERAGE($M$61:$M$65)*M78 -> 145.6361 | P78: =O78/1000/M78 -> 0.030496262 | R78: 8447.8455 | S78: =N78*1000000000*44/12*1/(R78*1000000) -> 2.0095434
A79: 2033 | D79: 10991015 | F79: =D79*S79/1000000 -> 20.281309 | J79: 2033 | M79: 4.4127782 | N79: =M79-O79/1000 -> 4.2782049 | O79: =AVERAGE($O$61:$O$65)/AVERAGE($M$61:$M$65)*M79 -> 134.57324 | P79: =O79/1000/M79 -> 0.030496262 | R79: 8501.0941 | S79: =N79*1000000000*44/12*1/(R79*1000000) -> 1.8452626
... A96: 2050 | D96: 11775563 | F96: =D96*S96/1000000 -> 2.8858313 | J96: 2050 | M96: 0.63383193 | N96: =M96-O96/1000 -> 0.61450242 | O96: =AVERAGE($O$61:$O$65)/AVERAGE($M$61:$M$65)*M96 -> 19.329505 | P96: =O96/1000/M96 -> 0.030496262 | R96: 9194.0269 | S96: =N96*1000000000*44/12*1/(R96*1000000) -> 0.2450695
E97: Historic responsibility
C98: Historic Emissions | E98: Budget for whole period
C99: MtCO2 | F99: MtCO2
B100: 1960-2021 | C100: =SUM(C6:C96) -> 3752.6466 | E100: 1960-2050 | F100: =SUM(D6:D96)/1000000*SUM(N6:N96)*44/12/SUM(R6:R96)*1000 -> 3144.2183
B101: 1970-2021 | C101: =SUM(C16:C96) -> 3119.2657 | E101: 1970-2050 | F101: =SUM(D16:D96)/1000000*SUM(N16:N96)*44/12/SUM(R16:R96)*1000 -> 2798.1965
B102: 1980-2021 | C102: =SUM(C26:C96) -> 2270.9508 | E102: 1980-2050 | F102: =SUM(D26:D96)/1000000*SUM(N26:N96)*44/12/SUM(R26:R96)*1000 -> 2408.4381
B103: 1990-2021 | C103: =SUM(C36:C96) -> 1654.5528 | E103: 1990-2050 | F103: =SUM(D36:D96)/1000000*SUM(N36:N96)*44/12/SUM(R36:R96)*1000 -> 2015.0211
B104: 2000-2021 | C104: =SUM(C46:C96) -> 1068.3693 | E104: 2000-2050 | F104: =SUM(D46:D96)/1000000*SUM(N46:N96)*44/12/SUM(R46:R96)*1000 -> 1607.4294
...

Sheet Net-Zero Territorial
A1: Year | B1: Historic emissions | C1: Economic capacity for transition | D1: Equal emissions per capita and year | E1: 1980 | F1: 1990 | G1: 2000 | H1: 2010
A2: 2015 | B2: ='Historical responsibility T'!C61 -> 43.634335
A3: 2016 | B3: ='Historical responsibility T'!C62 -> 43.293495
A4: 2017 | B4: ='Historical responsibility T'!C63 -> 42.624728
A5: 2018 | B5: ='Historical responsibility T'!C64 -> 42.126045
A6: 2019 | B6: ='Historical responsibility T'!C65 -> 40.966661
A7: 2020 | B7: ='Historical responsibility T'!C66 -> 38.653576
A8: 2021 | B8: ='Historical responsibility T'!C67 -> 39.465301 | C8: =B8 -> 39.465301 | D8: =C8 -> 39.465301 | E8: =D8 -> 39.465301 | F8: =E8 -> 39.465301 | G8: =F8 -> 39.465301 | H8: =G8 -> 39.465301
A9: 2022 | C9: =C$8-C$8*'Historical responsibility T'!$M$118*($A9-$A$8) -> 35.1753 | D9: =D$8-D$8*'Historical responsibility T'!$M$117*($A9-$A$8) -> 38.082689 | E9: =E$8-E$8*'Historical responsibility T'!$M$113*($A9-$A$8) -> 33.801105 | F9: =F$8-F$8*'Historical responsibility T'!$M$114*($A9-$A$8) -> 37.304903 | G9: =G$8-G$8*'Historical responsibility T'!$M$115*($A9-$A$8) -> 38.020647 | H9: =H$8-H$8*'Historical responsibility T'!$M$116*($A9-$A$8) -> 38.244476
A10: 2023 | C10: =C$8-C$8*'Historical responsibility T'!$M$118*($A10-$A$8) -> 30.885299 | D10: =D$8-D$8*'Historical responsibility T'!$M$117*($A10-$A$8) -> 36.700077 | E10: =E$8-E$8*'Historical responsibility T'!$M$113*($A10-$A$8) -> 28.136909 | F10: =F$8-F$8*'Historical responsibility T'!$M$114*($A10-$A$8) -> 35.144505 | G10: =G$8-G$8*'Historical responsibility T'!$M$115*($A10-$A$8) -> 36.575994 | H10: =H$8-H$8*'Historical responsibility T'!$M$116*($A10-$A$8) -> 37.023651
A11: 2024 | C11: =C$8-C$8*'Historical responsibility T'!$M$118*($A11-$A$8) -> 26.595298 | D11: =D$8-D$8*'Historical responsibility T'!$M$117*($A11-$A$8) -> 35.317465 | E11: =E$8-E$8*'Historical responsibility T'!$M$113*($A11-$A$8) -> 22.472713 | F11: =F$8-F$8*'Historical responsibility T'!$M$114*($A11-$A$8) -> 32.984107 | G11: =G$8-G$8*'Historical responsibility T'!$M$115*($A11-$A$8) -> 35.131341 | H11: =H$8-H$8*'Historical responsibility T'!$M$116*($A11-$A$8) -> 35.802826
A12: 2025 | C12: =C$8-C$8*'Historical responsibility T'!$M$118*($A12-$A$8) -> 22.305297 | D12: =D$8-D$8*'Historical responsibility T'!$M$117*($A12-$A$8) -> 33.934853 | E12: =E$8-E$8*'Historical responsibility T'!$M$113*($A12-$A$8) -> 16.808517 | F12: =F$8-F$8*'Historical responsibility T'!$M$114*($A12-$A$8) -> 30.823709 | G12: =G$8-G$8*'Historical responsibility T'!$M$115*($A12-$A$8) -> 33.686687 | H12: =H$8-H$8*'Historical responsibility T'!$M$116*($A12-$A$8) -> 34.582001
A13: 2026 | C13: =C$8-C$8*'Historical responsibility T'!$M$118*($A13-$A$8) -> 18.015296 | D13: =D$8-D$8*'Historical responsibility T'!$M$117*($A13-$A$8) -> 32.552241 | E13: =E$8-E$8*'Historical responsibility T'!$M$113*($A13-$A$8) -> 11.144321 | F13: =F$8-F$8*'Historical responsibility T'!$M$114*($A13-$A$8) -> 28.663311 | G13: =G$8-G$8*'Historical responsibility T'!$M$115*($A13-$A$8) -> 32.242034 | H13: =H$8-H$8*'Historical responsibility T'!$M$116*($A13-$A$8) -> 33.361176
A14: 2027 | C14: =C$8-C$8*'Historical responsibility T'!$M$118*($A14-$A$8) -> 13.725295 | D14: =D$8-D$8*'Historical responsibility T'!$M$117*($A14-$A$8) -> 31.16963 | E14: =E$8-E$8*'Historical responsibility T'!$M$113*($A14-$A$8) -> 5.4801252 | F14: =F$8-F$8*'Historical responsibility T'!$M$114*($A14-$A$8) -> 26.502913 | G14: =G$8-G$8*'Historical responsibility T'!$M$115*($A14-$A$8) -> 30.79738 | H14: =H$8-H$8*'Historical responsibility T'!$M$116*($A14-$A$8) -> 32.140351
A15: 2028 | C15: =C$8-C$8*'Historical responsibility T'!$M$118*($A15-$A$8) -> 9.4352944 | D15: =D$8-D$8*'Historical responsibility T'!$M$117*($A15-$A$8) -> 29.787018 | E15: =E$8-E$8*'Historical responsibility T'!$M$113*($A15-$A$8) -> -0.18407075 | F15: =F$8-F$8*'Historical responsibility T'!$M$114*($A15-$A$8) -> 24.342515 | G15: =G$8-G$8*'Historical responsibility T'!$M$115*($A15-$A$8) -> 29.352727 | H15: =H$8-H$8*'Historical responsibility T'!$M$116*($A15-$A$8) -> 30.919526
A16: 2029 | C16: =C$8-C$8*'Historical responsibility T'!$M$118*($A16-$A$8) -> 5.1452935 | D16: =D$8-D$8*'Historical responsibility T'!$M$117*($A16-$A$8) -> 28.404406 | E16: =E$8-E$8*'Historical responsibility T'!$M$113*($A16-$A$8) -> -5.8482667 | F16: =F$8-F$8*'Historical responsibility T'!$M$114*($A16-$A$8) -> 22.182117 | G16: =G$8-G$8*'Historical responsibility T'!$M$115*($A16-$A$8) -> 27.908074 | H16: =H$8-H$8*'Historical responsibility T'!$M$116*($A16-$A$8) -> 29.698701
A17: 2030 | C17: =C$8-C$8*'Historical responsibility T'!$M$118*($A17-$A$8) -> 0.85529259 | D17: =D$8-D$8*'Historical responsibility T'!$M$117*($A17-$A$8) -> 27.021794 | F17: =F$8-F$8*'Historical responsibility T'!$M$114*($A17-$A$8) -> 20.021719 | G17: =G$8-G$8*'Historical responsibility T'!$M$115*($A17-$A$8) -> 26.46342 | H17: =H$8-H$8*'Historical responsibility T'!$M$116*($A17-$A$8) -> 28.477877
A18: 2031 | C18: =C$8-C$8*'Historical responsibility T'!$M$118*($A18-$A$8) -> -3.4347083 | D18: =D$8-D$8*'Historical responsibility T'!$M$117*($A18-$A$8) -> 25.639182 | F18: =F$8-F$8*'Historical responsibility T'!$M$114*($A18-$A$8) -> 17.861321 | G18: =G$8-G$8*'Historical responsibility T'!$M$115*($A18-$A$8) -> 25.018767 | H18: =H$8-H$8*'Historical responsibility T'!$M$116*($A18-$A$8) -> 27.257052
A19: 2032 | D19: =D$8-D$8*'Historical responsibility T'!$M$117*($A19-$A$8) -> 24.256571 | F19: =F$8-F$8*'Historical responsibility T'!$M$114*($A19-$A$8) -> 15.700923 | G19: =G$8-G$8*'Historical responsibility T'!$M$115*($A19-$A$8) -> 23.574114 | H19: =H$8-H$8*'Historical responsibility T'!$M$116*($A19-$A$8) -> 26.036227
A20: 2033 | D20: =D$8-D$8*'Historical responsibility T'!$M$117*($A20-$A$8) -> 22.873959 | F20: =F$8-F$8*'Historical responsibility T'!$M$114*($A20-$A$8) -> 13.540525 | G20: =G$8-G$8*'Historical responsibility T'!$M$115*($A20-$A$8) -> 22.12946 | H20: =H$8-H$8*'Historical responsibility T'!$M$116*($A20-$A$8) -> 24.815402
A21: 2034 | D21: =D$8-D$8*'Historical responsibility T'!$M$117*($A21-$A$8) -> 21.491347 | F21: =F$8-F$8*'Historical responsibility T'!$M$114*($A21-$A$8) -> 11.380127 | G21: =G$8-G$8*'Historical responsibility T'!$M$115*($A21-$A$8) -> 20.684807 | H21: =H$8-H$8*'Historical responsibility T'!$M$116*($A21-$A$8) -> 23.594577
A22: 2035 | D22: =D$8-D$8*'Historical responsibility T'!$M$117*($A22-$A$8) -> 20.108735 | F22: =F$8-F$8*'Historical responsibility T'!$M$114*($A22-$A$8) -> 9.2197293 | G22: =G$8-G$8*'Historical responsibility T'!$M$115*($A22-$A$8) -> 19.240153 | H22: =H$8-H$8*'Historical responsibility T'!$M$116*($A22-$A$8) -> 22.373752
A23: 2036 | D23: =D$8-D$8*'Historical responsibility T'!$M$117*($A23-$A$8) -> 18.726123 | F23: =F$8-F$8*'Historical responsibility T'!$M$114*($A23-$A$8) -> 7.0593314 | G23: =G$8-G$8*'Historical responsibility T'!$M$115*($A23-$A$8) -> 17.7955 | H23: =H$8-H$8*'Historical responsibility T'!$M$116*($A23-$A$8) -> 21.152927
A24: 2037 | D24: =D$8-D$8*'Historical responsibility T'!$M$117*($A24-$A$8) -> 17.343511 | F24: =F$8-F$8*'Historical responsibility T'!$M$114*($A24-$A$8) -> 4.8989334 | G24: =G$8-G$8*'Historical responsibility T'!$M$115*($A24-$A$8) -> 16.350847 | H24: =H$8-H$8*'Historical responsibility T'!$M$116*($A24-$A$8) -> 19.932102
A25: 2038 | D25: =D$8-D$8*'Historical responsibility T'!$M$117*($A25-$A$8) -> 15.9609 | F25: =F$8-F$8*'Historical responsibility T'!$M$114*($A25-$A$8) -> 2.7385355 | G25: =G$8-G$8*'Historical responsibility T'!$M$115*($A25-$A$8) -> 14.906193 | H25: =H$8-H$8*'Historical responsibility T'!$M$116*($A25-$A$8) -> 18.711277
A26: 2039 | D26: =D$8-D$8*'Historical responsibility T'!$M$117*($A26-$A$8) -> 14.578288 | F26: =F$8-F$8*'Historical responsibility T'!$M$114*($A26-$A$8) -> 0.57813752 | G26: =G$8-G$8*'Historical responsibility T'!$M$115*($A26-$A$8) -> 13.46154 | H26: =H$8-H$8*'Historical responsibility T'!$M$116*($A26-$A$8) -> 17.490452
A27: 2040 | D27: =D$8-D$8*'Historical responsibility T'!$M$117*($A27-$A$8) -> 13.195676 | F27: =F$8-F$8*'Historical responsibility T'!$M$114*($A27-$A$8) -> -1.5822604 | G27: =G$8-G$8*'Historical responsibility T'!$M$115*($A27-$A$8) -> 12.016887 | H27: =H$8-H$8*'Historical responsibility T'!$M$116*($A27-$A$8) -> 16.269628
A28: 2041 | D28: =D$8-D$8*'Historical responsibility T'!$M$117*($A28-$A$8) -> 11.813064 | G28: =G$8-G$8*'Historical responsibility T'!$M$115*($A28-$A$8) -> 10.572233 | H28: =H$8-H$8*'Historical responsibility T'!$M$116*($A28-$A$8) -> 15.048803
A29: 2042 | D29: =D$8-D$8*'Historical responsibility T'!$M$117*($A29-$A$8) -> 10.430452 | G29: =G$8-G$8*'Historical responsibility T'!$M$115*($A29-$A$8) -> 9.1275798 | H29: =H$8-H$8*'Historical responsibility T'!$M$116*($A29-$A$8) -> 13.827978
A30: 2043 | D30: =D$8-D$8*'Historical responsibility T'!$M$117*($A30-$A$8) -> 9.0478405 | G30: =G$8-G$8*'Historical responsibility T'!$M$115*($A30-$A$8) -> 7.6829265 | H30: =H$8-H$8*'Historical responsibility T'!$M$116*($A30-$A$8) -> 12.607153
A31: 2044 | D31: =D$8-D$8*'Historical responsibility T'!$M$117*($A31-$A$8) -> 7.6652287 | G31: =G$8-G$8*'Historical responsibility T'!$M$115*($A31-$A$8) -> 6.2382731 | H31: =H$8-H$8*'Historical responsibility T'!$M$116*($A31-$A$8) -> 11.386328
A32: 2045 | D32: =D$8-D$8*'Historical responsibility T'!$M$117*($A32-$A$8) -> 6.2826168 | G32: =G$8-G$8*'Historical responsibility T'!$M$115*($A32-$A$8) -> 4.7936197 | H32: =H$8-H$8*'Historical responsibility T'!$M$116*($A32-$A$8) -> 10.165503
A33: 2046 | D33: =D$8-D$8*'Historical responsibility T'!$M$117*($A33-$A$8) -> 4.900005 | G33: =G$8-G$8*'Historical responsibility T'!$M$115*($A33-$A$8) -> 3.3489663 | H33: =H$8-H$8*'Historical responsibility T'!$M$116*($A33-$A$8) -> 8.9446781
A34: 2047 | D34: =D$8-D$8*'Historical responsibility T'!$M$117*($A34-$A$8) -> 3.5173932 | G34: =G$8-G$8*'Historical responsibility T'!$M$115*($A34-$A$8) -> 1.904313 | H34: =H$8-H$8*'Historical responsibility T'!$M$116*($A34-$A$8) -> 7.7238532
A35: 2048 | D35: =D$8-D$8*'Historical responsibility T'!$M$117*($A35-$A$8) -> 2.1347814 | G35: =G$8-G$8*'Historical responsibility T'!$M$115*($A35-$A$8) -> 0.4596596 | H35: =H$8-H$8*'Historical responsibility T'!$M$116*($A35-$A$8) -> 6.5030283
A36: 2049 | D36: =D$8-D$8*'Historical responsibility T'!$M$117*($A36-$A$8) -> 0.75216953 | G36: =G$8-G$8*'Historical responsibility T'!$M$115*($A36-$A$8) -> -0.98499377 | H36: =H$8-H$8*'Historical responsibility T'!$M$116*($A36-$A$8) -> 5.2822034
A37: 2050 | D37: =D$8-D$8*'Historical responsibility T'!$M$117*($A37-$A$8) -> -0.6304423 | G37: =G$8-G$8*'Historical responsibility T'!$M$115*($A37-$A$8) -> -2.4296471 | H37: =H$8-H$8*'Historical responsibility T'!$M$116*($A37-$A$8) -> 4.0613785
A38: 2051 | D38: =D$8-D$8*'Historical responsibility T'!$M$117*($A38-$A$8) -> -2.0130541 | H38: =H$8-H$8*'Historical responsibility T'!$M$116*($A38-$A$8) -> 2.8405536
A39: 2052 | H39: =H$8-H$8*'Historical responsibility T'!$M$116*($A39-$A$8) -> 1.6197287
A40: 2053 | H40: =H$8-H$8*'Historical responsibility T'!$M$116*($A40-$A$8) -> 0.3989038
...

Sheet Historical responsibility C
M2: Global Carbon Budget 2021 Friedlingstein, et al., 2021 | N2: IAMC AR6 Scenario Explorer 1.5C - Model: REMIND-MAgPIE 2.1-4.3 Scenario: DeepElec_SSP2_ HighRE_Budg900 2C - Model: WITCH 5.0 Scenario: CO_Bridge | O2: Statistics Sweden Population Projections | P2: SSP Database - Version 2.0 Data for SSP2
B3: Consumption-based emissions Sweden fossil (excl. LUC) | D3: Population | E3: Emissions | F3: Allocation per capita givet 1.5C Scenario | G3: Allocation per capita givet 2C Scenario | K3: Historic fossil emissions | L3: Historic LUC emissions | M3: 1.5C Scenario (World incl. LUC) | N3: 2C Scenario (World incl. LUC) | O3: Population SSP2 | P3: 1.5C Scenario per capita | Q3: 2C Scenario per capita
B4: MtC | C4: MtCO2 | E4: tCO2/capita | F4: MtCO2 | G4: MtCO2 | K4: GtC | L4: GtC | M4: GtC | O4: millions | P4: tCO2/capita | Q4: tCO2/capita
A5: 1990 | B5: 23.193254 | C5: =B5*44/12 -> 85.04193 | D5: 8590630 | E5: =C5*1000000/D5 -> 9.8993822 | F5: =D5*P5/1000000 -> 43.809653 | G5: =D5*Q5/1000000 -> 43.809653 | J5: 1990 | K5: 6.2069671 | L5: 1.1733564 | M5: =L5+K5 -> 7.3803235 | N5: =M5 -> 7.3803235 | O5: 5306.425 | P5: =M5*1000000000*44/12*1/(O5*1000000) -> 5.099702 | Q5: =N5*1000000000*44/12*1/(O5*1000000) -> 5.099702
A6: 1991 | B6: 22.955046 | C6: =B6*44/12 -> 84.168501 | D6: 8644119 | E6: =C6*1000000/D6 -> 9.7370827 | F6: =D6*P6/1000000 -> 44.039933 | G6: =D6*Q6/1000000 -> 44.039933 | J6: 1991 | K6: 6.3402869 | L6: 1.1495868 | M6: =L6+K6 -> 7.4898736 | N6: =M6 -> 7.4898736 | O6: 5390.3878 | P6: =M6*1000000000*44/12*1/(O6*1000000) -> 5.0947856 | Q6: =N6*1000000000*44/12*1/(O6*1000000) -> 5.0947856
A7: 1992 | B7: 25.404237 | C7: =B7*44/12 -> 93.148868 | D7: 8692013 | E7: =C7*1000000/D7 -> 10.716605 | F7: =D7*P7/1000000 -> 42.826557 | G7: =D7*Q7/1000000 -> 42.826557 | J7: 1992 | K7: 6.1576276 | L7: 1.1985798 | M7: =L7+K7 -> 7.3562074 | N7: =M7 -> 7.3562074 | O7: 5474.3506 | P7: =M7*1000000000*44/12*1/(O7*1000000) -> 4.927116 | Q7: =N7*1000000000*44/12*1/(O7*1000000) -> 4.927116
A8: 1993 | B8: 23.602983 | C8: =B8*44/12 -> 86.54427 | D8: 8745109 | E8: =C8*1000000/D8 -> 9.8963054 | F8: =D8*P8/1000000 -> 42.650128 | G8: =D8*Q8/1000000 -> 42.650128 | J8: 1993 | K8: 6.2213795 | L8: 1.1717227 | M8: =L8+K8 -> 7.3931022 | N8: =M8 -> 7.3931022 | O8: 5558.3134 | P8: =M8*1000000000*44/12*1/(O8*1000000) -> 4.8770264 | Q8: =N8*1000000000*44/12*1/(O8*1000000) -> 4.8770264
A9: 1994 | B9: 23.384994 | C9: =B9*44/12 -> 85.744979 | D9: 8816381 | E9: =C9*1000000/D9 -> 9.7256436 | F9: =D9*P9/1000000 -> 43.42594 | G9: =D9*Q9/1000000 -> 43.42594 | J9: 1994 | K9: 6.2654062 | L9: 1.3141153 | M9: =L9+K9 -> 7.5795215 | N9: =M9 -> 7.5795215 | O9: 5642.2762 | P9: =M9*1000000000*44/12*1/(O9*1000000) -> 4.925597 | Q9: =N9*1000000000*44/12*1/(O9*1000000) -> 4.925597
A10: 1995 | B10: 23.119241 | C10: =B10*44/12 -> 84.770552 | D10: 8837496 | E10: =C10*1000000/D10 -> 9.592146 | F10: =D10*P10/1000000 -> 43.571924 | G10: =D10*Q10/1000000 -> 43.571924 | J10: 1995 | K10: 6.3989097 | L10: 1.3008212 | M10: =L10+K10 -> 7.6997309 | N10: =M10 -> 7.6997309 | O10: 5726.239 | P10: =M10*1000000000*44/12*1/(O10*1000000) -> 4.9303473 | Q10: =N10*1000000000*44/12*1/(O10*1000000) -> 4.9303473
A11: 1996 | B11: 24.379453 | C11: =B11*44/12 -> 89.391327 | D11: 8844499 | E11: =C11*1000000/D11 -> 10.106997 | F11: =D11*P11/1000000 -> 44.192687 | G11: =D11*Q11/1000000 -> 44.192687 | J11: 1996 | K11: 6.5900779 | L11: 1.3212384 | M11: =L11+K11 -> 7.9113164 | N11: =M11 -> 7.9113164 | O11: 5805.5452 | P11: =M11*1000000000*44/12*1/(O11*1000000) -> 4.9966298 | Q11: =N11*1000000000*44/12*1/(O11*1000000) -> 4.9966298
A12: 1997 | B12: 22.962746 | C12: =B12*44/12 -> 84.196736 | D12: 8847625 | E12: =C12*1000000/D12 -> 9.5163093 | F12: =D12*P12/1000000 -> 46.589237 | G12: =D12*Q12/1000000 -> 46.589237 | J12: 1997 | K12: 6.6306989 | L12: 1.8205902 | M12: =L12+K12 -> 8.4512891 | N12: =M12 -> 8.4512891 | O12: 5884.8514 | P12: =M12*1000000000*44/12*1/(O12*1000000) -> 5.2657336 | Q12: =N12*1000000000*44/12*1/(O12*1000000) -> 5.2657336
A13: 1998 | B13: 23.188196 | C13: =B13*44/12 -> 85.023386 | D13: 8854322 | E13: =C13*1000000/D13 -> 9.6024728 | F13: =D13*P13/1000000 -> 43.584268 | G13: =D13*Q13/1000000 -> 43.584268 | J13: 1998 | K13: 6.6053587 | L13: 1.4013149 | M13: =L13+K13 -> 8.0066736 | N13: =M13 -> 8.0066736 | O13: 5964.1576 | P13: =M13*1000000000*44/12*1/(O13*1000000) -> 4.9223721 | Q13: =N13*1000000000*44/12*1/(O13*1000000) -> 4.9223721
A14: 1999 | B14: 21.981831 | C14: =B14*44/12 -> 80.600046 | D14: 8861426 | E14: =C14*1000000/D14 -> 9.0956067 | F14: =D14*P14/1000000 -> 43.415777 | G14: =D14*Q14/1000000 -> 43.415777 | J14: 1999 | K14: 6.6907376 | L14: 1.3845584 | M14: =L14+K14 -> 8.0752961 | N14: =M14 -> 8.0752961 | O14: 6043.4638 | P14: =M14*1000000000*44/12*1/(O14*1000000) -> 4.899412 | Q14: =N14*1000000000*44/12*1/(O14*1000000) -> 4.899412
A15: 2000 | B15: 22.464073 | C15: =B15*44/12 -> 82.368268 | D15: 8882792 | E15: =C15*1000000/D15 -> 9.2727904 | F15: =D15*P15/1000000 -> 43.217446 | G15: =D15*Q15/1000000 -> 43.217446 | J15: 2000 | K15: 6.8859607 | L15: 1.2383424 | M15: =L15+K15 -> 8.1243031 | N15: =M15 -> 8.1243031 | O15: 6122.77 | P15: =M15*1000000000*44/12*1/(O15*1000000) -> 4.8652997 | Q15: =N15*1000000000*44/12*1/(O15*1000000) -> 4.8652997
A16: 2001 | B16: 21.321408 | C16: =B16*44/12 -> 78.178497 | D16: 8909128 | E16: =C16*1000000/D16 -> 8.7751008 | F16: =D16*P16/1000000 -> 42.585324 | G16: =D16*Q16/1000000 -> 42.585324 | J16: 2001 | K16: 6.9451827 | L16: 1.1367123 | M16: =L16+K16 -> 8.081895 | N16: =M16 -> 8.081895 | O16: 6199.5458 | P16: =M16*1000000000*44/12*1/(O16*1000000) -> 4.7799655 | Q16: =N16*1000000000*44/12*1/(O16*1000000) -> 4.7799655
... A34: 2019 | B34: 18.528676 | C34: =B34*44/12 -> 67.938479 | D34: 10327553 | E34: =C34*1000000/D34 -> 6.5783713 | F34: =D34*P34/1000000 -> 54.794294 | G34: =D34*Q34/1000000 -> 54.794294 | J34: 2019 | K34: 10.016143 | L34: 1.0440531 | M34: =L34+K34 -> 11.060196 | N34: =M34 -> 11.060196 | O34: 7643.5719 | P34: =M34*1000000000*44/12*1/(O34*1000000) -> 5.3056415 | Q34: =N34*1000000000*44/12*1/(O34*1000000) -> 5.3056415
A35: 2020 | D35: 10379295 | F35: =D35*P35/1000000 -> 51.187339 | G35: =D35*Q35/1000000 -> 51.187339 | J35: 2020 | K35: 9.4999578 | L35: 0.87608978 | M35: =L35+K35 -> 10.376048 | N35: =M35 -> 10.376048 | O35: 7714.5161 | P35: =M35*1000000000*44/12*1/(O35*1000000) -> 4.9316778 | Q35: =N35*1000000000*44/12*1/(O35*1000000) -> 4.9316778
A36: 2021 | D36: 10428301 | F36: =D36*P36/1000000 -> 54.514965 | G36: =D36*Q36/1000000 -> 51.932368 | J36: 2021 | M36: ='IPCC IMPs'!F14/1000 -> 11.092523 | N36: ='IPCC IMPs'!G14/1000 -> 10.567024 | O36: 7780.3578 | P36: =M36*1000000000*44/12*1/(O36*1000000) -> 5.227598 | Q36: =N36*1000000000*44/12*1/(O36*1000000) -> 4.9799453
A37: 2022 | D37: 10477130 | F37: =D37*P37/1000000 -> 51.357696 | G37: =D37*Q37/1000000 -> 51.180177 | J37: 2022 | M37: ='IPCC IMPs'!F15/1000 -> 10.489411 | N37: ='IPCC IMPs'!G15/1000 -> 10.453155 | O37: 7846.1995 | P37: =M37*1000000000*44/12*1/(O37*1000000) -> 4.901886 | Q37: =N37*1000000000*44/12*1/(O37*1000000) -> 4.8849425
A38: 2023 | D38: 10523969 | F38: =D38*P38/1000000 -> 48.216562 | G38: =D38*Q38/1000000 -> 50.425817 | J38: 2023 | M38: ='IPCC IMPs'!F16/1000 -> 9.8863002 | N38: ='IPCC IMPs'!G16/1000 -> 10.339285 | O38: 7912.0412 | P38: =M38*1000000000*44/12*1/(O38*1000000) -> 4.5815949 | Q38: =N38*1000000000*44/12*1/(O38*1000000) -> 4.7915209
A39: 2024 | D39: 10569942 | F39: =D39*P39/1000000 -> 45.097614 | G39: =D39*Q39/1000000 -> 49.674935 | J39: 2024 | M39: ='IPCC IMPs'!F17/1000 -> 9.283189 | N39: ='IPCC IMPs'!G17/1000 -> 10.225415 | O39: 7977.8829 | P39: =M39*1000000000*44/12*1/(O39*1000000) -> 4.2665905 | Q39: =N39*1000000000*44/12*1/(O39*1000000) -> 4.6996413
A40: 2025 | D40: 10616595 | F40: =D40*P40/1000000 -> 42.007139 | G40: =D40*Q40/1000000 -> 48.934709 | J40: 2025 | M40: ='IPCC IMPs'!F18/1000 -> 8.6800778 | N40: ='IPCC IMPs'!G18/1000 -> 10.111545 | O40: 8043.7246 | P40: =M40*1000000000*44/12*1/(O40*1000000) -> 3.9567431 | Q40: =N40*1000000000*44/12*1/(O40*1000000) -> 4.6092658
A41: 2026 | D41: 10663635 | F41: =D41*P41/1000000 -> 38.815428 | G41: =D41*Q41/1000000 -> 47.980324 | J41: 2026 | M41: ='IPCC IMPs'!F19/1000 -> 8.0442745 | N41: ='IPCC IMPs'!G19/1000 -> 9.9436466 | O41: 8103.2494 | P41: =M41*1000000000*44/12*1/(O41*1000000) -> 3.639981 | Q41: =N41*1000000000*44/12*1/(O41*1000000) -> 4.4994342
A42: 2027 | D42: 10710874 | F42: =D42*P42/1000000 -> 35.64406 | G42: =D42*Q42/1000000 -> 47.033638 | J42: 2027 | M42: ='IPCC IMPs'!F20/1000 -> 7.4084713 | N42: ='IPCC IMPs'!G20/1000 -> 9.7757483 | O42: 8162.7741 | P42: =M42*1000000000*44/12*1/(O42*1000000) -> 3.3278386 | Q42: =N42*1000000000*44/12*1/(O42*1000000) -> 4.3912045
A43: 2028 | D43: 10758403 | F43: =D43*P43/1000000 -> 32.492698 | G43: =D43*Q43/1000000 -> 46.094827 | J43: 2028 | M43: ='IPCC IMPs'!F21/1000 -> 6.7726681 | N43: ='IPCC IMPs'!G21/1000 -> 9.6078499 | O43: 8222.2989 | P43: =M43*1000000000*44/12*1/(O43*1000000) -> 3.0202157 | Q43: =N43*1000000000*44/12*1/(O43*1000000) -> 4.2845418
A44: 2029 | D44: 10805992 | F44: =D44*P44/1000000 -> 29.360041 | G44: =D44*Q44/1000000 -> 45.162696 | J44: 2029 | M44: ='IPCC IMPs'!F22/1000 -> 6.1368649 | N44: ='IPCC IMPs'!G22/1000 -> 9.4399516 | O44: 8281.8236 | P44: =M44*1000000000*44/12*1/(O44*1000000) -> 2.7170149 | Q44: =N44*1000000000*44/12*1/(O44*1000000) -> 4.1794123
A45: 2030 | D45: 10853866 | F45: =D45*P45/1000000 -> 26.246182 | G45: =D45*Q45/1000000 -> 44.238006 | J45: 2030 | M45: ='IPCC IMPs'!F23/1000 -> 5.5010616 | N45: ='IPCC IMPs'!G23/1000 -> 9.2720532 | O45: 8341.3484 | P45: =M45*1000000000*44/12*1/(O45*1000000) -> 2.4181413 | Q45: =N45*1000000000*44/12*1/(O45*1000000) -> 4.0757833
A46: 2031 | D46: 10900734 | F46: =D46*P46/1000000 -> 24.46509 | G46: =D46*Q46/1000000 -> 42.007258 | J46: 2031 | M46: ='IPCC IMPs'!F24/1000 -> 5.1383005 | N46: ='IPCC IMPs'!G24/1000 -> 8.8226086 | O46: 8394.597 | P46: =M46*1000000000*44/12*1/(O46*1000000) -> 2.2443526 | Q46: =N46*1000000000*44/12*1/(O46*1000000) -> 3.8536174
A47: 2032 | D47: 10946282 | F47: =D47*P47/1000000 -> 22.688957 | G47: =D47*Q47/1000000 -> 39.78155 | J47: 2032 | M47: ='IPCC IMPs'!F25/1000 -> 4.7755393 | N47: ='IPCC IMPs'!G25/1000 -> 8.3731641 | O47: 8447.8455 | P47: =M47*1000000000*44/12*1/(O47*1000000) -> 2.0727546 | Q47: =N47*1000000000*44/12*1/(O47*1000000) -> 3.6342523
... A65: 2050 | D65: 11775563 | F65: =D65*P65/1000000 -> 2.9766067 | G65: =D65*Q65/1000000 -> 13.905317 | J65: 2050 | M65: ='IPCC IMPs'!F43/1000 -> 0.63383193 | N65: ='IPCC IMPs'!G43/1000 -> 2.9609669 | O65: 9194.0269 | P65: =M65*1000000000*44/12*1/(O65*1000000) -> 0.25277829 | Q65: =N65*1000000000*44/12*1/(O65*1000000) -> 1.1808622
E66: Historic responsibility
C67: Historic Emissions | E67: Budget for whole period
C68: MtCO2 | F68: MtCO2
B69: 1990-2021 | C69: =SUM(C5:C65) -> 2448.441 | E69: 1990-2050 | F69: =SUM(D5:D65)/1000000*SUM(M5:M65)*44/12/SUM(O5:O65)*1000 -> 2072.9637 | G69: =SUM(D5:D65)/1000000*SUM(N5:N65)*44/12/SUM(O5:O65)*1000 -> 2445.5113
B70: 2000-2021 | C70: =SUM(C15:C65) -> 1589.8104 | E70: 2000-2050 | F70: =SUM(D15:D65)/1000000*SUM(M15:M65)*44/12/SUM(O15:O65)*1000 -> 1655.8262 | G70: =SUM(D15:D65)/1000000*SUM(N15:N65)*44/12/SUM(O15:O65)*1000 -> 2020.757
B71: 2010-2021 | C71: =SUM(C25:C65) -> 745.53771 | E71: 2010-2050 | F71: =SUM(D25:D65)/1000000*SUM(M25:M65)*44/12/SUM(O25:O65)*1000 -> 1202.3999 | G71: =SUM(D25:D65)/1000000*SUM(N25:N65)*44/12/SUM(O25:O65)*1000 -> 1563.2459
E72: 2020-2050 | F72: =SUM(F35:F65) -> 686.66879 | G72: =SUM(G35:G65) -> 1042.6761
D75: Start year historic responsibility | E75: 1.5C Budget 2020-2050 | F75: 2C Budget 2020-2050 | J75: Linear reduction
E76: MtCO2 | F76: MtCO2 | J76: Number of years until net-zero | K76: Year for net-zero | M76: Linear reduction rate | N76: Exponential reduction rate
D77: 1990 | E77: =F69-C69 -> -375.47725 | F77: =G69-C69 -> -2.9296692 | I77: 1990 | J77: =E77/$C$34*2 -> -11.053449 | K77: =2019+J77 -> 2007.9466 | M77: =(0-$C$34)/($A$34-K77)/$C$34 -> -0.090469501 | N77: =M77*2 -> -0.180939
...

Sheet Net-Zero Consumption-based
A1: Year | B1: Historic emissions | C1: Economic capacity for transition | D1: Equal emissions per capita and year | E1: 2000 | F1: 2010
A2: 2015 | B2: ='Historical responsibility C'!C30 -> 70.746299
A3: 2016 | B3: ='Historical responsibility C'!C31 -> 69.990736
A4: 2017 | B4: ='Historical responsibility C'!C32 -> 70.598838
A5: 2018 | B5: ='Historical responsibility C'!C33 -> 71.105752
A6: 2019 | B6: ='Historical responsibility C'!C34 -> 67.938479 | C6: =$B6 -> 67.938479 | D6: =$B6 -> 67.938479 | E6: =$B6 -> 67.938479 | F6: =$B6 -> 67.938479
A7: 2020 | C7: =C$6-C$6*'Historical responsibility C'!$M$81*($A7-$A$6) -> 57.184808 | D7: =D$6-D$6*'Historical responsibility C'!$M$80*($A7-$A$6) -> 64.577589 | E7: =E$6-E$6*'Historical responsibility C'!$M$78*($A7-$A$6) -> 32.979926 | F7: =F$6-F$6*'Historical responsibility C'!$M$79*($A7-$A$6) -> 62.887025
A8: 2021 | C8: =C$6-C$6*'Historical responsibility C'!$M$81*($A8-$A$6) -> 46.431138 | D8: =D$6-D$6*'Historical responsibility C'!$M$80*($A8-$A$6) -> 61.216698 | E8: =E$6-E$6*'Historical responsibility C'!$M$78*($A8-$A$6) -> -1.9786275 | F8: =F$6-F$6*'Historical responsibility C'!$M$79*($A8-$A$6) -> 57.835571
A9: 2022 | C9: =C$6-C$6*'Historical responsibility C'!$M$81*($A9-$A$6) -> 35.677467 | D9: =D$6-D$6*'Historical responsibility C'!$M$80*($A9-$A$6) -> 57.855808 | F9: =F$6-F$6*'Historical responsibility C'!$M$79*($A9-$A$6) -> 52.784117
A10: 2023 | C10: =C$6-C$6*'Historical responsibility C'!$M$81*($A10-$A$6) -> 24.923796 | D10: =D$6-D$6*'Historical responsibility C'!$M$80*($A10-$A$6) -> 54.494918 | F10: =F$6-F$6*'Historical responsibility C'!$M$79*($A10-$A$6) -> 47.732663
A11: 2024 | C11: =C$6-C$6*'Historical responsibility C'!$M$81*($A11-$A$6) -> 14.170126 | D11: =D$6-D$6*'Historical responsibility C'!$M$80*($A11-$A$6) -> 51.134027 | F11: =F$6-F$6*'Historical responsibility C'!$M$79*($A11-$A$6) -> 42.681209
A12: 2025 | C12: =C$6-C$6*'Historical responsibility C'!$M$81*($A12-$A$6) -> 3.4164552 | D12: =D$6-D$6*'Historical responsibility C'!$M$80*($A12-$A$6) -> 47.773137 | F12: =F$6-F$6*'Historical responsibility C'!$M$79*($A12-$A$6) -> 37.629755
A13: 2026 | C13: =C$6-C$6*'Historical responsibility C'!$M$81*($A13-$A$6) -> -7.3372154 | D13: =D$6-D$6*'Historical responsibility C'!$M$80*($A13-$A$6) -> 44.412247 | F13: =F$6-F$6*'Historical responsibility C'!$M$79*($A13-$A$6) -> 32.578301
A14: 2027 | D14: =D$6-D$6*'Historical responsibility C'!$M$80*($A14-$A$6) -> 41.051357 | F14: =F$6-F$6*'Historical responsibility C'!$M$79*($A14-$A$6) -> 27.526847
A15: 2028 | D15: =D$6-D$6*'Historical responsibility C'!$M$80*($A15-$A$6) -> 37.690466 | F15: =F$6-F$6*'Historical responsibility C'!$M$79*($A15-$A$6) -> 22.475393
A16: 2029 | D16: =D$6-D$6*'Historical responsibility C'!$M$80*($A16-$A$6) -> 34.329576 | F16: =F$6-F$6*'Historical responsibility C'!$M$79*($A16-$A$6) -> 17.423939
A17: 2030 | D17: =D$6-D$6*'Historical responsibility C'!$M$80*($A17-$A$6) -> 30.968686 | F17: =F$6-F$6*'Historical responsibility C'!$M$79*($A17-$A$6) -> 12.372485
A18: 2031 | D18: =D$6-D$6*'Historical responsibility C'!$M$80*($A18-$A$6) -> 27.607796 | F18: =F$6-F$6*'Historical responsibility C'!$M$79*($A18-$A$6) -> 7.3210308
A19: 2032 | D19: =D$6-D$6*'Historical responsibility C'!$M$80*($A19-$A$6) -> 24.246905 | F19: =F$6-F$6*'Historical responsibility C'!$M$79*($A19-$A$6) -> 2.2695768
A20: 2033 | D20: =D$6-D$6*'Historical responsibility C'!$M$80*($A20-$A$6) -> 20.886015 | F20: =F$6-F$6*'Historical responsibility C'!$M$79*($A20-$A$6) -> -2.7818772
A21: 2034 | D21: =D$6-D$6*'Historical responsibility C'!$M$80*($A21-$A$6) -> 17.525125
A22: 2035 | D22: =D$6-D$6*'Historical responsibility C'!$M$80*($A22-$A$6) -> 14.164235
A23: 2036 | D23: =D$6-D$6*'Historical responsibility C'!$M$80*($A23-$A$6) -> 10.803344
A24: 2037 | D24: =D$6-D$6*'Historical responsibility C'!$M$80*($A24-$A$6) -> 7.4424541
A25: 2038 | D25: =D$6-D$6*'Historical responsibility C'!$M$80*($A25-$A$6) -> 4.0815638
A26: 2039 | D26: =D$6-D$6*'Historical responsibility C'!$M$80*($A26-$A$6) -> 0.72067359
A27: 2040 | D27: =D$6-D$6*'Historical responsibility C'!$M$80*($A27-$A$6) -> -2.6402167
A28: 2041
A29: 2042
A30: 2043
A31: 2044
A32: 2045
A33: 2046
A34: 2047
A35: 2048
A36: 2049
A37: 2050
A38: 2051
A39: 2052
... A42: 2055

Sheet Historical responsibility C+T
C2: =U19 -> 0.33 | M2: Global Carbon Budget 2021 Friedlingstein, et al., 2021 | N2: IAMC AR6 Scenario Explorer 1.5C - Model: REMIND-MAgPIE 2.1-4.3 Scenario: DeepElec_SSP2_ HighRE_Budg900 2C - Model: WITCH 5.0 Scenario: CO_Bridge | O2: Statistics Sweden Population Projections | P2: SSP Database - Version 2.0 Data for SSP2
B3: Territorial emissions Sweden fossil (excl. LUC) | D3: Population | E3: Emissions | F3: Allocation per capita givet 1.5C Scenario | G3: Allocation per capita givet 2C Scenario | K3: Historic fossil emissions | L3: Historic LUC emissions | M3: 1.5C Scenario (World incl. LUC) | N3: 2C Scenario (World incl. LUC) | O3: Population SSP2 | P3: 1.5C Scenario per capita | Q3: 2C Scenario per capita
B4: MtC | C4: MtCO2 | E4: tCO2/capita | F4: MtCO2 | G4: MtCO2 | K4: GtC | L4: GtC | M4: GtC | O4: millions | P4: tCO2/capita | Q4: tCO2/capita
A5: 1990 | B5: =$C$2*'Historical responsibility C'!B5+(1-$C$2)*'Historical responsibility T'!B36 -> 18.145992 | C5: =B5*44/12 -> 66.535302 | D5: 8590630 | E5: =C5*1000000/D5 -> 7.7451016 | F5: =D5*P5/1000000 -> 43.809653 | G5: =D5*Q5/1000000 -> 43.809653 | J5: 1990 | K5: 6.2069671 | L5: 1.1733564 | M5: =L5+K5 -> 7.3803235 | N5: =M5 -> 7.3803235 | O5: 5306.425 | P5: =M5*1000000000*44/12*1/(O5*1000000) -> 5.099702 | Q5: =N5*1000000000*44/12*1/(O5*1000000) -> 5.099702
A6: 1991 | B6: =$C$2*'Historical responsibility C'!B6+(1-$C$2)*'Historical responsibility T'!B37 -> 18.135868 | C6: =B6*44/12 -> 66.498182 | D6: 8644119 | E6: =C6*1000000/D6 -> 7.6928813 | F6: =D6*P6/1000000 -> 44.039933 | G6: =D6*Q6/1000000 -> 44.039933 | J6: 1991 | K6: 6.3402869 | L6: 1.1495868 | M6: =L6+K6 -> 7.4898736 | N6: =M6 -> 7.4898736 | O6: 5390.3878 | P6: =M6*1000000000*44/12*1/(O6*1000000) -> 5.0947856 | Q6: =N6*1000000000*44/12*1/(O6*1000000) -> 5.0947856
A7: 1992 | B7: =$C$2*'Historical responsibility C'!B7+(1-$C$2)*'Historical responsibility T'!B38 -> 18.896977 | C7: =B7*44/12 -> 69.288917 | D7: 8692013 | E7: =C7*1000000/D7 -> 7.9715616 | F7: =D7*P7/1000000 -> 42.826557 | G7: =D7*Q7/1000000 -> 42.826557 | J7: 1992 | K7: 6.1576276 | L7: 1.1985798 | M7: =L7+K7 -> 7.3562074 | N7: =M7 -> 7.3562074 | O7: 5474.3506 | P7: =M7*1000000000*44/12*1/(O7*1000000) -> 4.927116 | Q7: =N7*1000000000*44/12*1/(O7*1000000) -> 4.927116
A8: 1993 | B8: =$C$2*'Historical responsibility C'!B8+(1-$C$2)*'Historical responsibility T'!B39 -> 18.310076 | C8: =B8*44/12 -> 67.136944 | D8: 8745109 | E8: =C8*1000000/D8 -> 7.6770849 | F8: =D8*P8/1000000 -> 42.650128 | G8: =D8*Q8/1000000 -> 42.650128 | J8: 1993 | K8: 6.2213795 | L8: 1.1717227 | M8: =L8+K8 -> 7.3931022 | N8: =M8 -> 7.3931022 | O8: 5558.3134 | P8: =M8*1000000000*44/12*1/(O8*1000000) -> 4.8770264 | Q8: =N8*1000000000*44/12*1/(O8*1000000) -> 4.8770264
A9: 1994 | B9: =$C$2*'Historical responsibility C'!B9+(1-$C$2)*'Historical responsibility T'!B40 -> 18.688619 | C9: =B9*44/12 -> 68.524936 | D9: 8816381 | E9: =C9*1000000/D9 -> 7.7724563 | F9: =D9*P9/1000000 -> 43.42594 | G9: =D9*Q9/1000000 -> 43.42594 | J9: 1994 | K9: 6.2654062 | L9: 1.3141153 | M9: =L9+K9 -> 7.5795215 | N9: =M9 -> 7.5795215 | O9: 5642.2762 | P9: =M9*1000000000*44/12*1/(O9*1000000) -> 4.925597 | Q9: =N9*1000000000*44/12*1/(O9*1000000) -> 4.925597
A10: 1995 | B10: =$C$2*'Historical responsibility C'!B10+(1-$C$2)*'Historical responsibility T'!B41 -> 18.493887 | C10: =B10*44/12 -> 67.810918 | D10: 8837496 | E10: =C10*1000000/D10 -> 7.6730918 | F10: =D10*P10/1000000 -> 43.571924 | G10: =D10*Q10/1000000 -> 43.571924 | J10: 1995 | K10: 6.3989097 | L10: 1.3008212 | M10: =L10+K10 -> 7.6997309 | N10: =M10 -> 7.6997309 | O10: 5726.239 | P10: =M10*1000000000*44/12*1/(O10*1000000) -> 4.9303473 | Q10: =N10*1000000000*44/12*1/(O10*1000000) -> 4.9303473
A11: 1996 | B11: =$C$2*'Historical responsibility C'!B11+(1-$C$2)*'Historical responsibility T'!B42 -> 19.629408 | C11: =B11*44/12 -> 71.974496 | D11: 8844499 | E11: =C11*1000000/D11 -> 8.1377697 | F11: =D11*P11/1000000 -> 44.192687 | G11: =D11*Q11/1000000 -> 44.192687 | J11: 1996 | K11: 6.5900779 | L11: 1.3212384 | M11: =L11+K11 -> 7.9113164 | N11: =M11 -> 7.9113164 | O11: 5805.5452 | P11: =M11*1000000000*44/12*1/(O11*1000000) -> 4.9966298 | Q11: =N11*1000000000*44/12*1/(O11*1000000) -> 4.9966298
A12: 1997 | B12: =$C$2*'Historical responsibility C'!B12+(1-$C$2)*'Historical responsibility T'!B43 -> 18.229536 | C12: =B12*44/12 -> 66.84163 | D12: 8847625 | E12: =C12*1000000/D12 -> 7.554754 | F12: =D12*P12/1000000 -> 46.589237 | G12: =D12*Q12/1000000 -> 46.589237 | J12: 1997 | K12: 6.6306989 | L12: 1.8205902 | M12: =L12+K12 -> 8.4512891 | N12: =M12 -> 8.4512891 | O12: 5884.8514 | P12: =M12*1000000000*44/12*1/(O12*1000000) -> 5.2657336 | Q12: =N12*1000000000*44/12*1/(O12*1000000) -> 5.2657336
A13: 1998 | B13: =$C$2*'Historical responsibility C'!B13+(1-$C$2)*'Historical responsibility T'!B44 -> 18.389999 | C13: =B13*44/12 -> 67.429997 | D13: 8854322 | E13: =C13*1000000/D13 -> 7.6154896 | F13: =D13*P13/1000000 -> 43.584268 | G13: =D13*Q13/1000000 -> 43.584268 | J13: 1998 | K13: 6.6053587 | L13: 1.4013149 | M13: =L13+K13 -> 8.0066736 | N13: =M13 -> 8.0066736 | O13: 5964.1576 | P13: =M13*1000000000*44/12*1/(O13*1000000) -> 4.9223721 | Q13: =N13*1000000000*44/12*1/(O13*1000000) -> 4.9223721
A14: 1999 | B14: =$C$2*'Historical responsibility C'!B14+(1-$C$2)*'Historical responsibility T'!B45 -> 17.468098 | C14: =B14*44/12 -> 64.049694 | D14: 8861426 | E14: =C14*1000000/D14 -> 7.2279217 | F14: =D14*P14/1000000 -> 43.415777 | G14: =D14*Q14/1000000 -> 43.415777 | J14: 1999 | K14: 6.6907376 | L14: 1.3845584 | M14: =L14+K14 -> 8.0752961 | N14: =M14 -> 8.0752961 | O14: 6043.4638 | P14: =M14*1000000000*44/12*1/(O14*1000000) -> 4.899412 | Q14: =N14*1000000000*44/12*1/(O14*1000000) -> 4.899412
A15: 2000 | B15: =$C$2*'Historical responsibility C'!B15+(1-$C$2)*'Historical responsibility T'!B46 -> 17.417393 | C15: =B15*44/12 -> 63.863775 | D15: 8882792 | E15: =C15*1000000/D15 -> 7.189606 | F15: =D15*P15/1000000 -> 43.217446 | G15: =D15*Q15/1000000 -> 43.217446 | J15: 2000 | K15: 6.8859607 | L15: 1.2383424 | M15: =L15+K15 -> 8.1243031 | N15: =M15 -> 8.1243031 | O15: 6122.77 | P15: =M15*1000000000*44/12*1/(O15*1000000) -> 4.8652997 | Q15: =N15*1000000000*44/12*1/(O15*1000000) -> 4.8652997
A16: 2001 | B16: =$C$2*'Historical responsibility C'!B16+(1-$C$2)*'Historical responsibility T'!B47 -> 17.20998 | C16: =B16*44/12 -> 63.103259 | D16: 8909128 | E16: =C16*1000000/D16 -> 7.0829894 | F16: =D16*P16/1000000 -> 42.585324 | G16: =D16*Q16/1000000 -> 42.585324 | J16: 2001 | K16: 6.9451827 | L16: 1.1367123 | M16: =L16+K16 -> 8.081895 | N16: =M16 -> 8.081895 | O16: 6199.5458 | P16: =M16*1000000000*44/12*1/(O16*1000000) -> 4.7799655 | Q16: =N16*1000000000*44/12*1/(O16*1000000) -> 4.7799655
A17: 2002 | B17: =$C$2*'Historical responsibility C'!B17+(1-$C$2)*'Historical responsibility T'!B48 -> 17.618378 | C17: =B17*44/12 -> 64.600718 | D17: 8940788 | E17: =C17*1000000/D17 -> 7.2253943 | F17: =D17*P17/1000000 -> 43.84175 | G17: =D17*Q17/1000000 -> 43.84175 | J17: 2002 | K17: 7.1058552 | L17: 1.2876979 | M17: =L17+K17 -> 8.3935532 | N17: =M17 -> 8.3935532 | O17: 6276.3216 | P17: =M17*1000000000*44/12*1/(O17*1000000) -> 4.9035667 | Q17: =N17*1000000000*44/12*1/(O17*1000000) -> 4.9035667
A18: 2003 | B18: =$C$2*'Historical responsibility C'!B18+(1-$C$2)*'Historical responsibility T'!B49 -> 18.232386 | C18: =B18*44/12 -> 66.852083 | D18: 8975670 | E18: =C18*1000000/D18 -> 7.448144 | F18: =D18*P18/1000000 -> 45.8885 | G18: =D18*Q18/1000000 -> 45.8885 | J18: 2003 | K18: 7.4682056 | L18: 1.3901084 | M18: =L18+K18 -> 8.858314 | N18: =M18 -> 8.858314 | O18: 6353.0974 | P18: =M18*1000000000*44/12*1/(O18*1000000) -> 5.1125431 | Q18: =N18*1000000000*44/12*1/(O18*1000000) -> 5.1125431 | V18: Mainly producer responsibility | AP18: Mainly consumer responsibility
A19: 2004 | B19: =$C$2*'Historical responsibility C'!B19+(1-$C$2)*'Historical responsibility T'!B50 -> 18.241897 | C19: =B19*44/12 -> 66.886957 | D19: 9011392 | E19: =C19*1000000/D19 -> 7.4224889 | F19: =D19*P19/1000000 -> 46.564029 | G19: =D19*Q19/1000000 -> 46.564029 | J19: 2004 | K19: 7.8122934 | L19: 1.2489886 | M19: =L19+K19 -> 9.061282 | N19: =M19 -> 9.061282 | O19: 6429.8732 | P19: =M19*1000000000*44/12*1/(O19*1000000) -> 5.1672404 | Q19: =N19*1000000000*44/12*1/(O19*1000000) -> 5.1672404 | U19: 0.33 | V19: 1e-07 | W19: 0.05 | X19: 0.1 | Y19: 0.15 | Z19: 0.2 | AA19: 0.25 | AB19: 0.3 | AC19: 0.35 | AD19: 0.4 | AE19: 0.45 | AF19: 0.5 | AG19: 0.55 | AH19: 0.6 | AI19: 0.65 | AJ19: 0.7 | AK19: 0.75 | AL19: 0.8 | AM19: 0.85 | AN19: 0.9 | AO19: 0.95 | AP19: 1
A20: 2005 | B20: =$C$2*'Historical responsibility C'!B20+(1-$C$2)*'Historical responsibility T'!B51 -> 17.630072 | C20: =B20*44/12 -> 64.643598 | D20: 9047752 | E20: =C20*1000000/D20 -> 7.1447138 | F20: =D20*P20/1000000 -> 46.776896 | G20: =D20*Q20/1000000 -> 46.776896 | J20: 2005 | K20: 8.0783377 | L20: 1.1189719 | M20: =L20+K20 -> 9.1973096 | N20: =M20 -> 9.1973096 | O20: 6522.9121 | P20: =M20*1000000000*44/12*1/(O20*1000000) -> 5.170002 | Q20: =N20*1000000000*44/12*1/(O20*1000000) -> 5.170002 | S20: Budget | T20: 1990 | U20: =E77 -> 169.94592 | V20: 438.58709 | W20: 397.88395 | X20: 357.18073 | Y20: 316.47751 | Z20: 275.77429 | AA20: 235.07107 | AB20: 194.36785 | AC20: 153.66463 | AD20: 112.96141 | AE20: 72.258185 | AF20: 31.554963 | AG20: -9.148258 | AH20: -49.851479 | AI20: -90.554701 | AJ20: -131.25792 | AK20: -171.96114 | AL20: -212.66436 | AM20: -253.36759 | AN20: -294.07081 | AO20: -334.77403 | AP20: -375.47725
A21: 2006 | B21: =$C$2*'Historical responsibility C'!B21+(1-$C$2)*'Historical responsibility T'!B52 -> 17.825401 | C21: =B21*44/12 -> 65.359802 | D21: 9113257 | E21: =C21*1000000/D21 -> 7.1719477 | F21: =D21*P21/1000000 -> 48.626252 | G21: =D21*Q21/1000000 -> 48.626252 | J21: 2006 | K21: 8.3459964 | L21: 1.2663711 | M21: =L21+K21 -> 9.6123676 | N21: =M21 -> 9.6123676 | O21: 6605.4837 | P21: =M21*1000000000*44/12*1/(O21*1000000) -> 5.335771 | Q21: =N21*1000000000*44/12*1/(O21*1000000) -> 5.335771 | T21: 2000 | U21: =E78 -> 435.29514 | V21: 617.17891 | W21: 589.62081 | X21: 562.06265 | Y21: 534.5045 | Z21: 506.94634 | AA21: 479.38819 | AB21: 451.83003 | AC21: 424.27187 | AD21: 396.71372 | AE21: 369.15556 | AF21: 341.59741 | AG21: 314.03925 | AH21: 286.48109 | AI21: 258.92294 | AJ21: 231.36478 | AK21: 203.80663 | AL21: 176.24847 | AM21: 148.69031 | AN21: 121.13216 | AO21: 93.574002 | AP21: 66.015846
A22: 2007 | B22: =$C$2*'Historical responsibility C'!B22+(1-$C$2)*'Historical responsibility T'!B53 -> 17.895975 | C22: =B22*44/12 -> 65.618574 | D22: 9182927 | E22: =C22*1000000/D22 -> 7.1457144 | F22: =D22*P22/1000000 -> 48.828253 | G22: =D22*Q22/1000000 -> 48.828253 | J22: 2007 | K22: 8.5943901 | L22: 1.1044203 | M22: =L22+K22 -> 9.6988104 | N22: =M22 -> 9.6988104 | O22: 6688.0552 | P22: =M22*1000000000*44/12*1/(O22*1000000) -> 5.3172864 | Q22: =N22*1000000000*44/12*1/(O22*1000000) -> 5.3172864 | T22: 2010 | U22: =E79 -> 630.49211 | V22: 716.01129 | W22: 703.05386 | X22: 690.09641 | Y22: 677.13895 | Z22: 664.1815 | AA22: 651.22404 | AB22: 638.26659 | AC22: 625.30913 | AD22: 612.35168 | AE22: 599.39422 | AF22: 586.43676 | AG22: 573.47931 | AH22: 560.52185 | AI22: 547.5644 | AJ22: 534.60694 | AK22: 521.64949 | AL22: 508.69203 | AM22: 495.73458 | AN22: 482.77712 | AO22: 469.81967 | AP22: 456.86221
A23: 2008 | B23: =$C$2*'Historical responsibility C'!B23+(1-$C$2)*'Historical responsibility T'!B54 -> 17.183798 | C23: =B23*44/12 -> 63.007259 | D23: 9256347 | E23: =C23*1000000/D23 -> 6.8069249 | F23: =D23*P23/1000000 -> 49.532588 | G23: =D23*Q23/1000000 -> 49.532588 | J23: 2008 | K23: 8.751576 | L23: 1.1296046 | M23: =L23+K23 -> 9.8811805 | N23: =M23 -> 9.8811805 | O23: 6770.6268 | P23: =M23*1000000000*44/12*1/(O23*1000000) -> 5.3512026 | Q23: =N23*1000000000*44/12*1/(O23*1000000) -> 5.3512026 | T23: Inget historiskt ansvar - lika per capita utsläpp per år | U23: =E80 -> 672.78007 | V23: 665.93937 | W23: 666.97584 | X23: 668.01231 | Y23: 669.04878 | Z23: 670.08525 | AA23: 671.12172 | AB23: 672.15819 | AC23: 673.19466 | AD23: 674.23113 | AE23: 675.26761 | AF23: 676.30408 | AG23: 677.34055 | AH23: 678.37702 | AI23: 679.41349 | AJ23: 680.44996 | AK23: 681.48643 | AL23: 682.52291 | AM23: 683.55938 | AN23: 684.59585 | AO23: 685.63232 | AP23: 686.66879
A24: 2009 | B24: =$C$2*'Historical responsibility C'!B24+(1-$C$2)*'Historical responsibility T'!B55 -> 15.353164 | C24: =B24*44/12 -> 56.294934 | D24: 9340682 | E24: =C24*1000000/D24 -> 6.0268548 | F24: =D24*P24/1000000 -> 49.283423 | G24: =D24*Q24/1000000 -> 49.283423 | J24: 2009 | K24: 8.62538 | L24: 1.2361466 | M24: =L24+K24 -> 9.8615265 | N24: =M24 -> 9.8615265 | O24: 6853.1983 | P24: =M24*1000000000*44/12*1/(O24*1000000) -> 5.2762125 | Q24: =N24*1000000000*44/12*1/(O24*1000000) -> 5.2762125 | T24: Ekonomisk kapacitet | U24: =E81 -> 214.60751 | V24: 214.60751 | W24: 214.60751 | X24: 214.60751 | Y24: 214.60751 | Z24: 214.60751 | AA24: 214.60751 | AB24: 214.60751 | AC24: 214.60751 | AD24: 214.60751 | AE24: 214.60751 | AF24: 214.60751 | AG24: 214.60751 | AH24: 214.60751 | AI24: 214.60751 | AJ24: 214.60751 | AK24: 214.60751 | AL24: 214.60751 | AM24: 214.60751 | AN24: 214.60751 | AO24: 214.60751 | AP24: 214.60751 | AT24: 1e-07 | AU24: 0.05 | AV24: 0.1 | AW24: 0.15 | AX24: 0.2 | AY24: 0.25 | AZ24: 0.3 | BA24: 0.35 | BB24: 0.4 | BC24: 0.45 | BD24: 0.5 | BE24: 0.55 | BF24: 0.6 | BG24: 0.65 | BH24: 0.7 | BI24: 0.75 | BJ24: 0.8 | BK24: 0.85 | BL24: 0.9 | BM24: 0.95 | BN24: 1
A25: 2010 | B25: =$C$2*'Historical responsibility C'!B25+(1-$C$2)*'Historical responsibility T'!B56 -> 17.493222 | C25: =B25*44/12 -> 64.141814 | D25: 9415570 | E25: =C25*1000000/D25 -> 6.8123134 | F25: =D25*P25/1000000 -> 51.10635 | G25: =D25*Q25/1000000 -> 51.10635 | J25: 2010 | K25: 9.0993761 | L25: 1.1678115 | M25: =L25+K25 -> 10.267188 | N25: =M25 -> 10.267188 | O25: 6935.7699 | P25: =M25*1000000000*44/12*1/(O25*1000000) -> 5.4278552 | Q25: =N25*1000000000*44/12*1/(O25*1000000) -> 5.4278552 | S25: Netto-noll | T25: 1990 | U25: =K77 -> 2025.8159 | V25: 2040.4119 | W25: 2037.8057 | X25: 2035.3605 | Y25: 2033.0618 | Z25: 2030.8968 | AA25: 2028.8542 | AB25: 2026.924 | AC25: 2025.097 | AD25: 2023.3652 | AE25: 2021.7214 | AF25: 2020.159 | AG25: 2018.6721 | AH25: 2017.2554 | AI25: 2015.904 | AJ25: 2014.6135 | AK25: 2013.3799 | AL25: 2012.1995 | AM25: 2011.069 | AN25: 2009.9851 | AO25: 2008.9452 | AP25: 2007.9466 | AS25: Historic
A26: 2011 | B26: =$C$2*'Historical responsibility C'!B26+(1-$C$2)*'Historical responsibility T'!B57 -> 16.476552 | C26: =B26*44/12 -> 60.414024 | D26: 9482855 | E26: =C26*1000000/D26 -> 6.3708687 | F26: =D26*P26/1000000 -> 53.116996 | G26: =D26*Q26/1000000 -> 53.116996 | J26: 2011 | K26: 9.4064171 | L26: 1.318542 | M26: =L26+K26 -> 10.724959 | N26: =M26 -> 10.724959 | O26: 7020.5749 | P26: =M26*1000000000*44/12*1/(O26*1000000) -> 5.6013718 | Q26: =N26*1000000000*44/12*1/(O26*1000000) -> 5.6013718 | T26: 2000 | U26: =K78 -> 2036.4581 | V26: 2049.1308 | W26: 2046.868 | X26: 2044.745 | Y26: 2042.7492 | Z26: 2040.8695 | AA26: 2039.0961 | AB26: 2037.4202 | AC26: 2035.8339 | AD26: 2034.3303 | AE26: 2032.9031 | AF26: 2031.5466 | AG26: 2030.2557 | AH26: 2029.0256 | AI26: 2027.8523 | AJ26: 2026.7319 | AK26: 2025.6608 | AL26: 2024.636 | AM26: 2023.6544 | AN26: 2022.7134 | AO26: 2021.8105 | AP26: 2020.9434 | AS26: Ekonomisk kapacitet | AT26: 214.60751 | AU26: 214.60751 | AV26: 214.60751 | AW26: 214.60751 | AX26: 214.60751 | AY26: 214.60751 | AZ26: 214.60751 | BA26: 214.60751 | BB26: 214.60751 | BC26: 214.60751 | BD26: 214.60751 | BE26: 214.60751 | BF26: 214.60751 | BG26: 214.60751 | BH26: 214.60751 | BI26: 214.60751 | BJ26: 214.60751 | BK26: 214.60751 | BL26: 214.60751 | BM26: 214.60751 | BN26: 214.60751
A27: 2012 | B27: =$C$2*'Historical responsibility C'!B27+(1-$C$2)*'Historical responsibility T'!B58 -> 15.624339 | C27: =B27*44/12 -> 57.289243 | D27: 9555893 | E27: =C27*1000000/D27 -> 5.9951741 | F27: =D27*P27/1000000 -> 53.359432 | G27: =D27*Q27/1000000 -> 53.359432 | J27: 2012 | K27: 9.54439 | L27: 1.2763209 | M27: =L27+K27 -> 10.820711 | N27: =M27 -> 10.820711 | O27: 7105.3799 | P27: =M27*1000000000*44/12*1/(O27*1000000) -> 5.5839294 | Q27: =N27*1000000000*44/12*1/(O27*1000000) -> 5.5839294 | T27: 2010 | U27: =K79 -> 2044.2868 | V27: 2053.9558 | W27: 2052.2293 | X27: 2050.6095 | Y27: 2049.0868 | Z27: 2047.6526 | AA27: 2046.2995 | AB27: 2045.0208 | AC27: 2043.8105 | AD27: 2042.6633 | AE27: 2041.5744 | AF27: 2040.5394 | AG27: 2039.5544 | AH27: 2038.6159 | AI27: 2037.7207 | AJ27: 2036.8658 | AK27: 2036.0486 | AL27: 2035.2667 | AM27: 2034.5177 | AN27: 2033.7997 | AO27: 2033.1108 | AP27: 2032.4493 | AS27: Inget historiskt ansvar - lika per capita utsläpp per år | AT27: 665.93937 | AU27: 666.97584 | AV27: 668.01231 | AW27: 669.04878 | AX27: 670.08525 | AY27: 671.12172 | AZ27: 672.15819 | BA27: 673.19466 | BB27: 674.23113 | BC27: 675.26761 | BD27: 676.30408 | BE27: 677.34055 | BF27: 678.37702 | BG27: 679.41349 | BH27: 680.44996 | BI27: 681.48643 | BJ27: 682.52291 | BK27: 683.55938 | BL27: 684.59585 | BM27: 685.63232 | BN27: 686.66879
A28: 2013 | B28: =$C$2*'Historical responsibility C'!B28+(1-$C$2)*'Historical responsibility T'!B59 -> 15.010199 | C28: =B28*44/12 -> 55.037398 | D28: 9644864 | E28: =C28*1000000/D28 -> 5.7063944 | F28: =D28*P28/1000000 -> 53.153118 | G28: =D28*Q28/1000000 -> 53.153118 | J28: 2013 | K28: 9.6287403 | L28: 1.178163 | M28: =L28+K28 -> 10.806903 | N28: =M28 -> 10.806903 | O28: 7190.1849 | P28: =M28*1000000000*44/12*1/(O28*1000000) -> 5.5110282 | Q28: =N28*1000000000*44/12*1/(O28*1000000) -> 5.5110282 | T28: Inget historiskt ansvar - lika per capita utsläpp per år | U28: =K80 -> 2045.9828 | V28: 2051.5113 | W28: 2050.5241 | X28: 2049.598 | Y28: 2048.7273 | Z28: 2047.9073 | AA28: 2047.1336 | AB28: 2046.4025 | AC28: 2045.7105 | AD28: 2045.0545 | AE28: 2044.4319 | AF28: 2043.8401 | AG28: 2043.2769 | AH28: 2042.7403 | AI28: 2042.2285 | AJ28: 2041.7397 | AK28: 2041.2724 | AL28: 2040.8253 | AM28: 2040.3971 | AN28: 2039.9866 | AO28: 2039.5927 | AP28: 2039.2144 | AS28: 1990 | AT28: 438.58709 | AU28: 397.88395 | AV28: 357.18073 | AW28: 316.47751 | AX28: 275.77429 | AY28: 235.07107 | AZ28: 194.36785 | BA28: 153.66463 | BB28: 112.96141 | BC28: 72.258185 | BD28: 31.554963 | BE28: -9.148258 | BF28: -49.851479 | BG28: -90.554701 | BH28: -131.25792 | BI28: -171.96114 | BJ28: -212.66436 | BK28: -253.36759 | BL28: -294.07081 | BM28: -334.77403 | BN28: -375.47725
A29: 2014 | B29: =$C$2*'Historical responsibility C'!B29+(1-$C$2)*'Historical responsibility T'!B60 -> 14.425649 | C29: =B29*44/12 -> 52.894046 | D29: 9747355 | E29: =C29*1000000/D29 -> 5.4265025 | F29: =D29*P29/1000000 -> 53.760547 | G29: =D29*Q29/1000000 -> 53.760547 | J29: 2014 | K29: 9.697487 | L29: 1.2455499 | M29: =L29+K29 -> 10.943037 | N29: =M29 -> 10.943037 | O29: 7274.9899 | P29: =M29*1000000000*44/12*1/(O29*1000000) -> 5.5153985 | Q29: =N29*1000000000*44/12*1/(O29*1000000) -> 5.5153985 | T29: Ekonomisk kapacitet | U29: =K81 -> 2027.6071 | V29: 2029.4772 | W29: 2029.1433 | X29: 2028.83 | Y29: 2028.5355 | Z29: 2028.2581 | AA29: 2027.9964 | AB29: 2027.7491 | AC29: 2027.515 | AD29: 2027.2931 | AE29: 2027.0825 | AF29: 2026.8824 | AG29: 2026.6919 | AH29: 2026.5104 | AI29: 2026.3372 | AJ29: 2026.1719 | AK29: 2026.0138 | AL29: 2025.8626 | AM29: 2025.7177 | AN29: 2025.5789 | AO29: 2025.4456 | AP29: 2025.3177 | AS29: 2000 | AT29: 617.17891 | AU29: 589.62081 | AV29: 562.06265 | AW29: 534.5045 | AX29: 506.94634 | AY29: 479.38819 | AZ29: 451.83003 | BA29: 424.27187 | BB29: 396.71372 | BC29: 369.15556 | BD29: 341.59741 | BE29: 314.03925 | BF29: 286.48109 | BG29: 258.92294 | BH29: 231.36478 | BI29: 203.80663 | BJ29: 176.24847 | BK29: 148.69031 | BL29: 121.13216 | BM29: 93.574002 | BN29: 66.015846
